<?xml version="1.0" ?>
<robot name="iris">
  <joint name="iris/ground_truth/odometry_sensorgt_joint" type="fixed">
    <parent link="base_link"/>
    <child link="iris/ground_truth/odometry_sensorgt_link"/>
    <origin rpy="0 0 0" xyz="0      0      0.19492"/>
    <axis xyz="0 0 1"/>
    <limit effort="0.0" lower="0.0" upper="0.0" velocity="0.0"/>
  </joint>
  <joint name="iris/imu_joint" type="fixed">
    <parent link="base_link"/>
    <child link="iris/imu_link"/>
    <origin rpy="0 0 0" xyz="0      0      0.19492"/>
    <axis xyz="0 0 1"/>
    <limit effort="0.0" lower="0.0" upper="0.0" velocity="0.0"/>
  </joint>
  <joint name="rotor_0_joint" type="revolute">
    <parent link="base_link"/>
    <child link="rotor_0"/>
    <origin rpy="0 0 0" xyz="0.13    -0.22     0.21792"/>
    <axis xyz="0 0 1"/>
    <limit effort="0.0" lower="-1e+16" upper="1e+16" velocity="0.0"/>
  </joint>
  <joint name="rotor_1_joint" type="revolute">
    <parent link="base_link"/>
    <child link="rotor_1"/>
    <origin rpy="0 0 0" xyz="-0.13     0.2      0.21792"/>
    <axis xyz="0 0 1"/>
    <limit effort="0.0" lower="-1e+16" upper="1e+16" velocity="0.0"/>
  </joint>
  <joint name="rotor_2_joint" type="revolute">
    <parent link="base_link"/>
    <child link="rotor_2"/>
    <origin rpy="0 0 0" xyz="0.13    0.22    0.21792"/>
    <axis xyz="0 0 1"/>
    <limit effort="0.0" lower="-1e+16" upper="1e+16" velocity="0.0"/>
  </joint>
  <joint name="rotor_3_joint" type="revolute">
    <parent link="base_link"/>
    <child link="rotor_3"/>
    <origin rpy="0 0 0" xyz="-0.13    -0.2      0.21792"/>
    <axis xyz="0 0 1"/>
    <limit effort="0.0" lower="-1e+16" upper="1e+16" velocity="0.0"/>
  </joint>
  <joint name="camera_mount" type="fixed">
    <parent link="base_link"/>
    <child link="camera_link"/>
    <origin rpy="-1.5707 0 0" xyz="0      0.17492      0"/>
    <axis xyz="0 0 1"/>
    <limit effort="0.0" lower="0.0" upper="0.0" velocity="0.0"/>
  </joint>
  <link name="base_link">
    <inertial>
      <mass value="1.5"/>
      <origin rpy="0 0 0" xyz="0 0 0"/>
      <inertia ixx="0.008" ixy="0" ixz="0" iyy="0.015" iyz="0" izz="0.017"/>
    </inertial>
    <collision name="base_link_collision">
      <origin rpy="0 0 0" xyz="0      0      0.11492"/>
      <geometry>
        <box size="0.47 0.47 0.23"/>
      </geometry>
    </collision>
    <visual name="base_link_visual">
      <origin rpy="0 0 0" xyz="0      0      0.19492"/>
      <geometry>
        <mesh filename="package://harpia_simulator/models/iris_base/meshes/iris.dae" scale="1.0 1.0 1.0"/>
      </geometry>
    </visual>
    <visual name="front_left_leg_visual">
      <origin rpy="0 0 0" xyz="0.123   0.22    0.08492"/>
      <geometry>
        <cylinder length="0.17" radius="0.005"/>
      </geometry>
    </visual>
    <visual name="front_right_leg_visual">
      <origin rpy="0 0 0" xyz="0.123   -0.22     0.08492"/>
      <geometry>
        <cylinder length="0.17" radius="0.005"/>
      </geometry>
    </visual>
    <visual name="rear_left_leg_visual">
      <origin rpy="0 0 0" xyz="-0.14     0.21     0.08492"/>
      <geometry>
        <cylinder length="0.17" radius="0.005"/>
      </geometry>
    </visual>
    <visual name="rear_right_leg_visual">
      <origin rpy="0 0 0" xyz="-0.14    -0.21     0.08492"/>
      <geometry>
        <cylinder length="0.17" radius="0.005"/>
      </geometry>
    </visual>
  </link>
  <link name="iris/ground_truth/odometry_sensorgt_link">
    <inertial>
      <mass value="0.15"/>
      <origin rpy="0 0 0" xyz="0 0 0"/>
      <inertia ixx="0.0001" ixy="0" ixz="0" iyy="0.0002" iyz="0" izz="0.0002"/>
    </inertial>
  </link>
  <link name="iris/imu_link">
    <inertial>
      <mass value="0.15"/>
      <origin rpy="0 0 0" xyz="0 0 0"/>
      <inertia ixx="0.00001" ixy="0" ixz="0" iyy="0.00002" iyz="0" izz="0.00002"/>
    </inertial>
  </link>
  <link name="rotor_0">
    <inertial>
      <mass value="0.025"/>
      <origin rpy="0 0 0" xyz="0 0 0"/>
      <inertia ixx="9.75e-06" ixy="0" ixz="0" iyy="0.000166704" iyz="0" izz="0.000167604"/>
    </inertial>
    <collision name="rotor_0_collision">
      <origin rpy="0 0 0" xyz="0 0 0"/>
      <geometry>
        <cylinder length="0.005" radius="0.1"/>
      </geometry>
    </collision>
    <visual name="rotor_0_visual">
      <origin rpy="0 0 0" xyz="0 0 0"/>
      <geometry>
        <mesh filename="package://harpia_simulator/models/iris_base/meshes/iris_prop_ccw.dae" scale="1 1 1"/>
      </geometry>
    </visual>
  </link>
  <link name="rotor_1">
    <inertial>
      <mass value="0.025"/>
      <origin rpy="0 0 0" xyz="0 0 0"/>
      <inertia ixx="9.75e-06" ixy="0" ixz="0" iyy="0.000166704" iyz="0" izz="0.000167604"/>
    </inertial>
    <collision name="rotor_1_collision">
      <origin rpy="0 0 0" xyz="0 0 0"/>
      <geometry>
        <cylinder length="0.005" radius="0.1"/>
      </geometry>
    </collision>
    <visual name="rotor_1_visual">
      <origin rpy="0 0 0" xyz="0 0 0"/>
      <geometry>
        <mesh filename="package://harpia_simulator/models/iris_base/meshes/iris_prop_ccw.dae" scale="1 1 1"/>
      </geometry>
    </visual>
  </link>
  <link name="rotor_2">
    <inertial>
      <mass value="0.025"/>
      <origin rpy="0 0 0" xyz="0 0 0"/>
      <inertia ixx="9.75e-06" ixy="0" ixz="0" iyy="0.000166704" iyz="0" izz="0.000167604"/>
    </inertial>
    <collision name="rotor_2_collision">
      <origin rpy="0 0 0" xyz="0 0 0"/>
      <geometry>
        <cylinder length="0.005" radius="0.1"/>
      </geometry>
    </collision>
    <visual name="rotor_2_visual">
      <origin rpy="0 0 0" xyz="0 0 0"/>
      <geometry>
        <mesh filename="package://harpia_simulator/models/iris_base/meshes/iris_prop_cw.dae" scale="1 1 1"/>
      </geometry>
    </visual>
  </link>
  <link name="rotor_3">
    <inertial>
      <mass value="0.025"/>
      <origin rpy="0 0 0" xyz="0 0 0"/>
      <inertia ixx="9.75e-06" ixy="0" ixz="0" iyy="0.000166704" iyz="0" izz="0.000167604"/>
    </inertial>
    <collision name="rotor_3_collision">
      <origin rpy="0 0 0" xyz="0 0 0"/>
      <geometry>
        <cylinder length="0.005" radius="0.1"/>
      </geometry>
    </collision>
    <visual name="rotor_3_visual">
      <origin rpy="0 0 0" xyz="0 0 0"/>
      <geometry>
        <mesh filename="package://harpia_simulator/models/iris_base/meshes/iris_prop_cw.dae" scale="1 1 1"/>
      </geometry>
    </visual>
  </link>
  <link name="camera_link">
    <inertial>
      <mass value="0.01"/>
      <origin rpy="0 0 0" xyz="0 0 0"/>
      <inertia ixx="0.001" ixy="0" ixz="0" iyy="0.001" iyz="0" izz="0.001"/>
    </inertial>
    <visual name="camera_link">
      <origin rpy="0     1.5707 0" xyz="0   0   0.15"/>
      <geometry>
        <cylinder length=".018" radius=".005"/>
      </geometry>
    </visual>
  </link>
</robot>
